<mujoco model="panda">
    <compiler angle="radian" meshdir="/home/dfki.uni-bremen.de/adanzglock/mujoco_test_ws/src/mujoco_ros2_pkgs/panda_simulation/meshes/mujoco/assets" autolimits="true"/>

    <option integrator="implicitfast"/>
    
    <default>
        <default class="panda">
            <material specular="0.5" shininess="0.25"/>
            <joint armature="0.1" damping="1" axis="0 0 1" range="-2.8973 2.8973"/>
            <general dyntype="none" biastype="affine" ctrlrange="-2.8973 2.8973" forcerange="-87 87"/>
            <default class="finger">
                <joint axis="0 1 0" type="slide" range="0 0.04"/>
            </default>

            <default class="visual">
                <geom type="mesh" contype="0" conaffinity="0" group="2"/>
            </default>
            <default class="collision">
                <geom type="mesh" group="3"/>
                <default class="fingertip_pad_collision_1">
                    <geom type="box" size="0.0085 0.004 0.0085" pos="0 0.0055 0.0445"/>
                </default>
                <default class="fingertip_pad_collision_2">
                    <geom type="box" size="0.003 0.002 0.003" pos="0.0055 0.002 0.05"/>
                </default>
                <default class="fingertip_pad_collision_3">
                    <geom type="box" size="0.003 0.002 0.003" pos="-0.0055 0.002 0.05"/>
                </default>
                <default class="fingertip_pad_collision_4">
                    <geom type="box" size="0.003 0.002 0.0035" pos="0.0055 0.002 0.0395"/>
                </default>
                <default class="fingertip_pad_collision_5">
                    <geom type="box" size="0.003 0.002 0.0035" pos="-0.0055 0.002 0.0395"/>
                </default>
            </default>
        </default>
    </default>

    <asset>
        <material class="panda" name="white" rgba="1 1 1 1"/>
        <material class="panda" name="off_white" rgba="0.901961 0.921569 0.929412 1"/>
        <material class="panda" name="black" rgba="0.25 0.25 0.25 1"/>
        <material class="panda" name="green" rgba="0 1 0 1"/>
        <material class="panda" name="light_blue" rgba="0.039216 0.541176 0.780392 1"/>

        <!-- Collision meshes -->
        <mesh name="link0_c" file="link0.stl"/>
        <mesh name="link1_c" file="link1.stl"/>
        <mesh name="link2_c" file="link2.stl"/>
        <mesh name="link3_c" file="link3.stl"/>
        <mesh name="link4_c" file="link4.stl"/>
        <mesh name="link5_c0" file="link5_collision_0.obj"/>
        <mesh name="link5_c1" file="link5_collision_1.obj"/>
        <mesh name="link5_c2" file="link5_collision_2.obj"/>
        <mesh name="link6_c" file="link6.stl"/>
        <mesh name="link7_c" file="link7.stl"/>
        <mesh name="hand_c" file="hand.stl"/>

        <!-- Visual meshes -->
        <mesh file="link0_0.obj"/>
        <mesh file="link0_1.obj"/>
        <mesh file="link0_2.obj"/>
        <mesh file="link0_3.obj"/>
        <mesh file="link0_4.obj"/>
        <mesh file="link0_5.obj"/>
        <mesh file="link0_7.obj"/>
        <mesh file="link0_8.obj"/>
        <mesh file="link0_9.obj"/>
        <mesh file="link0_10.obj"/>
        <mesh file="link0_11.obj"/>
        <mesh file="link1.obj"/>
        <mesh file="link2.obj"/>
        <mesh file="link3_0.obj"/>
        <mesh file="link3_1.obj"/>
        <mesh file="link3_2.obj"/>
        <mesh file="link3_3.obj"/>
        <mesh file="link4_0.obj"/>
        <mesh file="link4_1.obj"/>
        <mesh file="link4_2.obj"/>
        <mesh file="link4_3.obj"/>
        <mesh file="link5_0.obj"/>
        <mesh file="link5_1.obj"/>
        <mesh file="link5_2.obj"/>
        <mesh file="link6_0.obj"/>
        <mesh file="link6_1.obj"/>
        <mesh file="link6_2.obj"/>
        <mesh file="link6_3.obj"/>
        <mesh file="link6_4.obj"/>
        <mesh file="link6_5.obj"/>
        <mesh file="link6_6.obj"/>
        <mesh file="link6_7.obj"/>
        <mesh file="link6_8.obj"/>
        <mesh file="link6_9.obj"/>
        <mesh file="link6_10.obj"/>
        <mesh file="link6_11.obj"/>
        <mesh file="link6_12.obj"/>
        <mesh file="link6_13.obj"/>
        <mesh file="link6_14.obj"/>
        <mesh file="link6_15.obj"/>
        <mesh file="link6_16.obj"/>
        <mesh file="link7_0.obj"/>
        <mesh file="link7_1.obj"/>
        <mesh file="link7_2.obj"/>
        <mesh file="link7_3.obj"/>
        <mesh file="link7_4.obj"/>
        <mesh file="link7_5.obj"/>
        <mesh file="link7_6.obj"/>
        <mesh file="link7_7.obj"/>
        <mesh file="hand_0.obj"/>
        <mesh file="hand_1.obj"/>
        <mesh file="hand_2.obj"/>
        <mesh file="hand_3.obj"/>
        <mesh file="hand_4.obj"/>
        <mesh file="finger_0.obj"/>
        <mesh file="finger_1.obj"/>
    </asset>

    <worldbody>
        <light name="top" pos="0 0 2" mode="trackcom"/>
        <body name="link0" childclass="panda" pos="0.5 0 0.875" gravcomp="1">
            <inertial mass="2.814271300104062" pos="-0.025566 -2.87883e-05 0.057332"
                      fullinertia="0.0075390636364814695 0.010508017427382959 0.009864933638708275 -1.5053124574783335e-05 -0.0012144328835738973 1.0434803501032979e-05"/>
            <geom mesh="link0_0" material="off_white" class="visual"/>
            <geom mesh="link0_1" material="black" class="visual"/>
            <geom mesh="link0_2" material="off_white" class="visual"/>
            <geom mesh="link0_3" material="black" class="visual"/>
            <geom mesh="link0_4" material="off_white" class="visual"/>
            <geom mesh="link0_5" material="black" class="visual"/>
            <geom mesh="link0_7" material="white" class="visual"/>
            <geom mesh="link0_8" material="white" class="visual"/>
            <geom mesh="link0_9" material="black" class="visual"/>
            <geom mesh="link0_10" material="off_white" class="visual"/>
            <geom mesh="link0_11" material="white" class="visual"/>
            <geom mesh="link0_c" class="collision"/>
            <body name="panda_link1" pos="0 0 0.333" gravcomp="1">
                <inertial mass="2.6433170427227215" pos="-3.72212e-09 -0.0324958 -0.0675818"
                          fullinertia="0.017405076982879724 0.015352077935781732 0.005987891663073857 -8.687986369621078e-09 -1.6277819062920423e-08 0.004510855959102245"/>
                <joint name="panda_joint1" damping="21.75"/>
                <geom material="white" mesh="link1" class="visual"/>
                <geom mesh="link1_c" class="collision"/>
                <body name="panda_link2" quat="1 -1 0 0" gravcomp="1">
                    <inertial mass="2.6652755331661186" pos="3.17833e-07 -0.06861 0.0322285"
                              fullinertia="0.01778694005635383 0.006044133867952844 0.01571095500455695 8.70635625879119e-08 3.752072058394008e-08 -0.004599490295490376"/>
                    <joint name="panda_joint2" range="-1.7628 1.7628" damping="21.75"/>
                    <geom material="white" mesh="link2" class="visual"/>
                    <geom mesh="link2_c" class="collision"/>
                    <body name="panda_link3" pos="0 -0.316 0" quat="1 1 0 0" gravcomp="1">
                        <joint name="panda_joint3" damping="21.75"/>
                        <inertial mass="2.3293714829045733" pos="0.0469893 0.0316374 -0.031704"
                                  fullinertia="0.0075496764161139766 0.009680676080191398 0.007944557422008086 -0.0024320464513492225 -0.003250815048103007 -0.0021316282421730694"/>
                        <geom mesh="link3_0" material="white" class="visual"/>
                        <geom mesh="link3_1" material="white" class="visual"/>
                        <geom mesh="link3_2" material="white" class="visual"/>
                        <geom mesh="link3_3" material="black" class="visual"/>
                        <geom mesh="link3_c" class="collision"/>
                        <body name="panda_link4" pos="0.0825 0 0" quat="1 1 0 0" gravcomp="1">
                            <inertial mass="2.3104763646281508" pos="-0.0360505 0.0337069 0.0319019"
                                      fullinertia="0.007764568814864828 0.008015776929980149 0.009955882308071066 0.003371475204045935 -0.002343621113168248 0.0022917526161470624"/>
                            <joint name="panda_joint4" range="-3.0718 -0.0698" damping="21.75"/>
                            <geom mesh="link4_0" material="white" class="visual"/>
                            <geom mesh="link4_1" material="white" class="visual"/>
                            <geom mesh="link4_2" material="black" class="visual"/>
                            <geom mesh="link4_3" material="white" class="visual"/>
                            <geom mesh="link4_c" class="collision"/>
                            <body name="panda_link5" pos="-0.0825 0.384 0" quat="1 -1 0 0" gravcomp="1">
                                <inertial mass="2.6226426154892004" pos="-6.12525e-06 0.0610427 -0.104176"
                                          fullinertia="0.029070538014399377 0.027638529986528795 0.004251111234400737 6.208738268725568e-07 -1.0059151925023392e-05 -0.007424306477850814"/>
                                <joint name="panda_joint5" damping="3.0"/>
                                <geom mesh="link5_0" material="black" class="visual"/>
                                <geom mesh="link5_1" material="white" class="visual"/>
                                <geom mesh="link5_2" material="white" class="visual"/>
                                <geom mesh="link5_c0" class="collision"/>
                                <geom mesh="link5_c1" class="collision"/>
                                <geom mesh="link5_c2" class="collision"/>
                                <body name="panda_link6" quat="1 1 0 0" gravcomp="1">
                                    <inertial mass="1.5025804886626795" pos="0.051051 0.00910797 0.0106343"
                                              fullinertia="0.002940555801469018 0.00392105201248677 0.0054115603870960195 -0.00042391108351381507 0.000610007735338717 0.00012647545430836214"/>
                                    <joint name="panda_joint6" range="-0.0175 3.7525" damping="3.0"/>
                                    <geom mesh="link6_0" material="off_white" class="visual"/>
                                    <geom mesh="link6_1" material="white" class="visual"/>
                                    <geom mesh="link6_2" material="black" class="visual"/>
                                    <geom mesh="link6_3" material="white" class="visual"/>
                                    <geom mesh="link6_4" material="white" class="visual"/>
                                    <geom mesh="link6_5" material="white" class="visual"/>
                                    <geom mesh="link6_6" material="white" class="visual"/>
                                    <geom mesh="link6_7" material="light_blue" class="visual"/>
                                    <geom mesh="link6_8" material="light_blue" class="visual"/>
                                    <geom mesh="link6_9" material="black" class="visual"/>
                                    <geom mesh="link6_10" material="black" class="visual"/>
                                    <geom mesh="link6_11" material="white" class="visual"/>
                                    <geom mesh="link6_12" material="green" class="visual"/>
                                    <geom mesh="link6_13" material="white" class="visual"/>
                                    <geom mesh="link6_14" material="black" class="visual"/>
                                    <geom mesh="link6_15" material="black" class="visual"/>
                                    <geom mesh="link6_16" material="white" class="visual"/>
                                    <geom mesh="link6_c" class="collision"/>
                                    <body name="panda_link7" pos="0.088 0 0" quat="1 1 0 0" gravcomp="1">
                                        <inertial mass="0.5237668134788256" pos="0.0109695 0.0107965 0.0650412"
                                                  fullinertia="0.0008621467959726535 0.0008613100184801048 0.0006961139396618219 -0.00011871071570425467 3.866602604509339e-05 -9.057841649422724e-05"/>
                                        <joint name="panda_joint7" damping="3.0"/>
                                        <geom mesh="link7_0" material="white" class="visual"/>
                                        <geom mesh="link7_1" material="black" class="visual"/>
                                        <geom mesh="link7_2" material="black" class="visual"/>
                                        <geom mesh="link7_3" material="black" class="visual"/>
                                        <geom mesh="link7_4" material="black" class="visual"/>
                                        <geom mesh="link7_5" material="black" class="visual"/>
                                        <geom mesh="link7_6" material="black" class="visual"/>
                                        <geom mesh="link7_7" material="white" class="visual"/>
                                        <geom mesh="link7_c" class="collision"/>
                                        <body name="panda_hand" pos="0 0 0.107" quat="0.9238795 0 0 -0.3826834" gravcomp="1">
                                            <inertial mass="0.14060765127978503" pos="-6.7624e-06 0.00152435 0.0275912" 
                                                      fullinertia="0.0005365450414352072 7.70511954783727e-05 0.0004938176882694914 1.7911952957732454e-08 -2.320071910601251e-08 4.681149945315967e-08"/>
                                            <geom mesh="hand_0" material="off_white" class="visual"/>
                                            <geom mesh="hand_1" material="black" class="visual"/>
                                            <geom mesh="hand_2" material="black" class="visual"/>
                                            <geom mesh="hand_3" material="white" class="visual"/>
                                            <geom mesh="hand_4" material="off_white" class="visual"/>
                                            <geom mesh="hand_c" class="collision"/>
                                            <body name="panda_left_finger" pos="0 0 0.0584" gravcomp="1">
                                                <inertial mass="0.2238453537819424" pos="-6.2561e-06 0.00227781 -0.0277116" 
                                                          fullinertia="6.74804167363695e-05 6.627189221641395e-05 1.550396267804825e-05 -4.1027443646025676e-09 1.8693673970152995e-08 1.1967548474390802e-05"/>
                                                <joint name="panda_finger_joint1" class="finger"/>
                                                <geom mesh="finger_0" material="off_white" class="visual"/>
                                                <geom mesh="finger_1" material="black" class="visual"/>
                                                <geom mesh="finger_0" class="collision"/>
                                                <geom class="fingertip_pad_collision_1"/>
                                                <geom class="fingertip_pad_collision_2"/>
                                                <geom class="fingertip_pad_collision_3"/>
                                                <geom class="fingertip_pad_collision_4"/>
                                                <geom class="fingertip_pad_collision_5"/>
                                            </body>
                                            <body name="panda_right_finger" pos="0 0 0.0584" quat="0 0 0 1" gravcomp="1">
                                                <inertial mass="0.2238453537819424" pos="-6.2561e-06 0.00227781 -0.0277116" 
                                                          fullinertia="6.74804167363695e-05 6.627189221641395e-05 1.550396267804825e-05 -4.1027443646025676e-09 1.8693673970152995e-08 1.1967548474390802e-05"/>
                                                <joint name="panda_finger_joint2" class="finger"/>
                                                <geom mesh="finger_0" material="off_white" class="visual"/>
                                                <geom mesh="finger_1" material="black" class="visual"/>
                                                <geom mesh="finger_0" class="collision"/>
                                                <geom class="fingertip_pad_collision_1"/>
                                                <geom class="fingertip_pad_collision_2"/>
                                                <geom class="fingertip_pad_collision_3"/>
                                                <geom class="fingertip_pad_collision_4"/>
                                                <geom class="fingertip_pad_collision_5"/>
                                            </body>
                                        </body>
                                    </body>
                                </body>
                            </body>
                        </body>
                    </body>
                </body>
            </body>
        </body>
    </worldbody>

    <tendon>
        <fixed name="split">
            <joint joint="panda_finger_joint1" coef="0.5"/>
            <joint joint="panda_finger_joint2" coef="0.5"/>
        </fixed>
    </tendon>

    <equality>
        <joint joint1="panda_finger_joint1" joint2="panda_finger_joint2" solimp="0.95 0.99 0.001" solref="0.005 1"/>
    </equality>

    <actuator>
        <motor name="joint1_eff" joint="panda_joint1" gear="1"/>
        <motor name="joint2_eff" joint="panda_joint2" gear="1"/>
        <motor name="joint3_eff" joint="panda_joint3" gear="1"/>
        <motor name="joint4_eff" joint="panda_joint4" gear="1"/>
        <motor name="joint5_eff" joint="panda_joint5" gear="1"/>
        <motor name="joint6_eff" joint="panda_joint6" gear="1"/>
        <motor name="joint7_eff" joint="panda_joint7" gear="1"/>

        <motor name="finger_joint1_eff" joint="panda_finger_joint1" gear="10"/>
        <motor name="finger_joint2_eff" joint="panda_finger_joint2" gear="10"/>
    </actuator>

    <!--actuator>
        <general class="panda" name="actuator1" joint="panda_joint1" gainprm="4500" biasprm="0 -4500 -450"/>
        <general class="panda" name="actuator2" joint="panda_joint2" gainprm="4500" biasprm="0 -4500 -450"
                 ctrlrange="-1.7628 1.7628"/>
        <general class="panda" name="actuator3" joint="panda_joint3" gainprm="3500" biasprm="0 -3500 -350"/>
        <general class="panda" name="actuator4" joint="panda_joint4" gainprm="3500" biasprm="0 -3500 -350"
                 ctrlrange="-3.0718 -0.0698"/>
        <general class="panda" name="actuator5" joint="panda_joint5" gainprm="2000" biasprm="0 -2000 -200" forcerange="-12 12"/>
        <general class="panda" name="actuator6" joint="panda_joint6" gainprm="2000" biasprm="0 -2000 -200" forcerange="-12 12"
                 ctrlrange="-0.0175 3.7525"/>
        <general class="panda" name="actuator7" joint="panda_joint7" gainprm="2000" biasprm="0 -2000 -200" forcerange="-12 12"/>
        <general class="panda" name="actuator8" tendon="split" forcerange="-100 100" ctrlrange="0 255"
                 gainprm="0.01568627451 0 0" biasprm="0 -100 -10"/>
    </actuator-->

    <!--keyframe>
        <key name="home" qpos="0 0 0 -1.57079 0 1.57079 -0.7853 0.04 0.04" ctrl="0 0 0 -1.57079 0 1.57079 -0.7853 255"/>
    </keyframe-->
</mujoco>
